<?xml version="1.0" ?>
<!-- =================================================================================== -->
<!-- |    This document was autogenerated by xacro from anymal_d.urdf.xacro            | -->
<!-- |    EDITING THIS FILE BY HAND IS NOT RECOMMENDED                                 | -->
<!-- =================================================================================== -->
<!-- This file contains the description of the ANYmal robot. -->
<robot name="anymal">
  <!-- [kg * m^2] -->
  <!-- [m] -->
  <!-- [m] -->
  <!-- Base link -->
  <link name="base">
    <visual>
      <origin rpy="0 0 0" xyz="0 0 0"/>
      <geometry>
        <mesh filename="../meshes/base_3_6_0_mesh.dae" scale="1.0 1.0     1.0"/>
      </geometry>
    </visual>
    <collision>
      <origin rpy="0 0 0" xyz="0 0 0"/>
      <geometry>
        <box size="0.9 0.18 0.14"/>
      </geometry>
    </collision>
  </link>
  <!-- Fixed joint to add dummy inertia link -->
  <joint name="base_to_base_inertia" type="fixed">
    <parent link="base"/>
    <child link="base_inertia"/>
    <origin rpy="0 0 0" xyz="0 0 0"/>
  </joint>
  <!-- Dummy inertia link, because KDL cannot have inertia on the base link -->
  <link name="base_inertia">
    <inertial>
      <origin rpy="0 0 0" xyz="-0.01321 0.00166 0.04005"/>
      <mass value="7.43462"/>
      <inertia ixx="0.04541605821" ixy="6.643502e-05" ixz="0.00707061964" iyy="0.38928051881" iyz="0.00052107313" izz="0.4006278391"/>
    </inertial>
  </link>
  <!-- Fixed joint to add top shell link -->
  <joint name="base_to_body_top" type="fixed">
    <parent link="base"/>
    <child link="body_top"/>
    <origin rpy="0 0 0" xyz="0 0 0.144"/>
  </joint>
  <!-- Body top link -->
  <!-- Added as a separate link due to limitation in point_cloud_self_filter -->
  <link name="body_top">
  </link>
  <!-- [kg * m^2] -->
  <!-- Fixed joint base top shell -->
  <joint name="base_top_shell" type="fixed">
    <parent link="base"/>
    <child link="top_shell"/>
    <origin rpy="0 0 0" xyz="0 0 0"/>
  </joint>
  <!-- Top shell link -->
  <link name="top_shell">
    <visual>
      <origin rpy="0 0 0" xyz="0 0 0"/>
      <geometry>
        <mesh filename="../meshes/top_shell_3_6_0_mesh.dae" scale="1.0 1.0 1.0"/>
      </geometry>
    </visual>
    <inertial>
      <origin rpy="0 0 0" xyz="-0.02189 -0.00017 0.0728"/>
      <mass value="0.6"/>
      <inertia ixx="0.00393833203" ixy="1.80018e-05" ixz="0.0004825552" iyy="0.01831760633" iyz="3.57532e-06" izz="0.02159223804"/>
    </inertial>
  </link>
  <!-- [kg * m^2] -->
  <!-- Fixed joint base bottom shell -->
  <joint name="base_bottom_shell" type="fixed">
    <parent link="base"/>
    <child link="bottom_shell"/>
    <origin rpy="0 0 0" xyz="0 0 0"/>
  </joint>
  <!-- Sbottom shell link -->
  <link name="bottom_shell">
    <visual>
      <origin rpy="0 0 0" xyz="0 0 0"/>
      <geometry>
        <mesh filename="../meshes/bottom_shell_3_6_0_mesh.dae" scale="1.0 1.0 1.0"/>
      </geometry>
    </visual>
    <inertial>
      <origin rpy="0 0 0" xyz="-0.00752 0.0 -0.07033"/>
      <mass value="0.79"/>
      <inertia ixx="0.00725878565" ixy="8.87373e-06" ixz="0.00018931397" iyy="0.03410318674" iyz="1.39e-09" izz="0.04030282643"/>
    </inertial>
  </link>
  <!-- [kg * m^2] -->
  <!--  [m] -->
  <!-- Fixed joint base face -->
  <joint name="base_face_front" type="fixed">
    <parent link="base"/>
    <child link="face_front"/>
    <origin rpy="0 0 -0.0" xyz="0.4087 0 0.02067"/>
  </joint>
  <!-- Face structure link, visualization is part of base -->
  <link name="face_front">
    <inertial>
      <origin rpy="0 0 0" xyz="-0.04096 0.00272 -0.01935"/>
      <mass value="0.40664"/>
      <inertia ixx="0.00061593913" ixy="6.64511e-06" ixz="1.30718e-06" iyy="0.0006319674" iyz="5.02808e-06" izz="0.00054433005"/>
    </inertial>
  </link>
  <!-- [kg * m^2] -->
  <!-- Camera joint -->
  <joint name="face_front_to_depth_camera_front_lower_camera" type="fixed">
    <parent link="face_front"/>
    <child link="depth_camera_front_lower_camera"/>
    <origin rpy="0.0 1.0471975511965976 0" xyz="-0.04013 -0.025 -0.08094"/>
  </joint>
  <!-- Camera link -->
  <link name="depth_camera_front_lower_camera">
    <inertial>
      <origin rpy="0 0 0" xyz="-0.00449 -0.01991 -9e-05"/>
      <mass value="0.064"/>
      <inertia ixx="8.155372e-05" ixy="1.8442e-07" ixz="4.627e-08" iyy="7.42475e-06" iyz="2.1958e-07" izz="7.840441e-05"/>
    </inertial>
  </link>
  <!-- Camera parent joint -->
  <!-- Frame lies on the left ir camera according to any_realsense2_camera urdf. -->
  <joint name="depth_camera_front_lower_camera_to_camera_parent" type="fixed">
    <parent link="depth_camera_front_lower_camera"/>
    <child link="depth_camera_front_lower_camera_parent"/>
    <origin rpy="3.141592653589793 0.0 0.0" xyz="0.0 0.0 0.0"/>
  </joint>
  <!-- Camera parent link -->
  <link name="depth_camera_front_lower_camera_parent"/>
  <!-- simulation or bagfile_is_played -->
  <!-- simulation -->
  <!-- [kg * m^2] -->
  <!-- Camera joint -->
  <joint name="face_front_to_depth_camera_front_upper_camera" type="fixed">
    <parent link="face_front"/>
    <child link="depth_camera_front_upper_camera"/>
    <origin rpy="0.0 0.2617993877991494 0" xyz="-0.00964 -0.025 -0.04121"/>
  </joint>
  <!-- Camera link -->
  <link name="depth_camera_front_upper_camera">
    <inertial>
      <origin rpy="0 0 0" xyz="-0.00449 -0.01991 -9e-05"/>
      <mass value="0.064"/>
      <inertia ixx="8.155372e-05" ixy="1.8442e-07" ixz="4.627e-08" iyy="7.42475e-06" iyz="2.1958e-07" izz="7.840441e-05"/>
    </inertial>
  </link>
  <!-- Camera parent joint -->
  <!-- Frame lies on the left ir camera according to any_realsense2_camera urdf. -->
  <joint name="depth_camera_front_upper_camera_to_camera_parent" type="fixed">
    <parent link="depth_camera_front_upper_camera"/>
    <child link="depth_camera_front_upper_camera_parent"/>
    <origin rpy="3.141592653589793 0.0 0.0" xyz="0.0 0.0 0.0"/>
  </joint>
  <!-- Camera parent link -->
  <link name="depth_camera_front_upper_camera_parent"/>
  <!-- simulation or bagfile_is_played -->
  <!-- simulation -->
  <!-- [m] -->
  <!-- Camera joint -->
  <joint name="face_front_to_wide_angle_camera_front_camera" type="fixed">
    <parent link="face_front"/>
    <child link="wide_angle_camera_front_camera"/>
    <origin rpy="0 0 0" xyz="0.0 0.0 0.0"/>
  </joint>
  <!-- Camera link -->
  <link name="wide_angle_camera_front_camera">
    </link>
  <!-- Camera parent joint -->
  <joint name="wide_angle_camera_front_camera_to_camera_parent" type="fixed">
    <parent link="wide_angle_camera_front_camera"/>
    <child link="wide_angle_camera_front_camera_parent"/>
    <origin rpy="-1.5707963267948966 0.0 -1.5707963267948966" xyz="-0.00355 0.0 0.0"/>
  </joint>
  <!-- Camera parent link -->
  <link name="wide_angle_camera_front_camera_parent"/>
  <!-- simulation -->
  <!-- [kg * m^2] -->
  <!--  [m] -->
  <!-- Fixed joint base face -->
  <joint name="base_face_rear" type="fixed">
    <parent link="base"/>
    <child link="face_rear"/>
    <origin rpy="0 0 3.141592653589793" xyz="-0.4087 0 0.02067"/>
  </joint>
  <!-- Face structure link, visualization is part of base -->
  <link name="face_rear">
    <inertial>
      <origin rpy="0 0 0" xyz="-0.04096 0.00272 -0.01935"/>
      <mass value="0.40664"/>
      <inertia ixx="0.00061593913" ixy="6.64511e-06" ixz="1.30718e-06" iyy="0.0006319674" iyz="5.02808e-06" izz="0.00054433005"/>
    </inertial>
  </link>
  <!-- [kg * m^2] -->
  <!-- Camera joint -->
  <joint name="face_rear_to_depth_camera_rear_lower_camera" type="fixed">
    <parent link="face_rear"/>
    <child link="depth_camera_rear_lower_camera"/>
    <origin rpy="0.0 1.0471975511965976 0" xyz="-0.04013 -0.025 -0.08094"/>
  </joint>
  <!-- Camera link -->
  <link name="depth_camera_rear_lower_camera">
    <inertial>
      <origin rpy="0 0 0" xyz="-0.00449 -0.01991 -9e-05"/>
      <mass value="0.064"/>
      <inertia ixx="8.155372e-05" ixy="1.8442e-07" ixz="4.627e-08" iyy="7.42475e-06" iyz="2.1958e-07" izz="7.840441e-05"/>
    </inertial>
  </link>
  <!-- Camera parent joint -->
  <!-- Frame lies on the left ir camera according to any_realsense2_camera urdf. -->
  <joint name="depth_camera_rear_lower_camera_to_camera_parent" type="fixed">
    <parent link="depth_camera_rear_lower_camera"/>
    <child link="depth_camera_rear_lower_camera_parent"/>
    <origin rpy="3.141592653589793 0.0 0.0" xyz="0.0 0.0 0.0"/>
  </joint>
  <!-- Camera parent link -->
  <link name="depth_camera_rear_lower_camera_parent"/>
  <!-- simulation or bagfile_is_played -->
  <!-- simulation -->
  <!-- [kg * m^2] -->
  <!-- Camera joint -->
  <joint name="face_rear_to_depth_camera_rear_upper_camera" type="fixed">
    <parent link="face_rear"/>
    <child link="depth_camera_rear_upper_camera"/>
    <origin rpy="0.0 0.2617993877991494 0" xyz="-0.00964 -0.025 -0.04121"/>
  </joint>
  <!-- Camera link -->
  <link name="depth_camera_rear_upper_camera">
    <inertial>
      <origin rpy="0 0 0" xyz="-0.00449 -0.01991 -9e-05"/>
      <mass value="0.064"/>
      <inertia ixx="8.155372e-05" ixy="1.8442e-07" ixz="4.627e-08" iyy="7.42475e-06" iyz="2.1958e-07" izz="7.840441e-05"/>
    </inertial>
  </link>
  <!-- Camera parent joint -->
  <!-- Frame lies on the left ir camera according to any_realsense2_camera urdf. -->
  <joint name="depth_camera_rear_upper_camera_to_camera_parent" type="fixed">
    <parent link="depth_camera_rear_upper_camera"/>
    <child link="depth_camera_rear_upper_camera_parent"/>
    <origin rpy="3.141592653589793 0.0 0.0" xyz="0.0 0.0 0.0"/>
  </joint>
  <!-- Camera parent link -->
  <link name="depth_camera_rear_upper_camera_parent"/>
  <!-- simulation or bagfile_is_played -->
  <!-- simulation -->
  <!-- [m] -->
  <!-- Camera joint -->
  <joint name="face_rear_to_wide_angle_camera_rear_camera" type="fixed">
    <parent link="face_rear"/>
    <child link="wide_angle_camera_rear_camera"/>
    <origin rpy="0 0 0" xyz="0.0 0.0 0.0"/>
  </joint>
  <!-- Camera link -->
  <link name="wide_angle_camera_rear_camera">
    </link>
  <!-- Camera parent joint -->
  <joint name="wide_angle_camera_rear_camera_to_camera_parent" type="fixed">
    <parent link="wide_angle_camera_rear_camera"/>
    <child link="wide_angle_camera_rear_camera_parent"/>
    <origin rpy="-1.5707963267948966 0.0 -1.5707963267948966" xyz="-0.00355 0.0 0.0"/>
  </joint>
  <!-- Camera parent link -->
  <link name="wide_angle_camera_rear_camera_parent"/>
  <!-- simulation -->
  <!-- [kg * m^2] -->
  <!-- Fixed joint face face shell -->
  <joint name="base_face_shell_front" type="fixed">
    <parent link="face_front"/>
    <child link="face_shell_front"/>
    <origin rpy="0 0 0" xyz="0 0 0"/>
  </joint>
  <!-- Face shell link -->
  <link name="face_shell_front">
    <visual>
      <origin rpy="0 0 0" xyz="0 0 0"/>
      <geometry>
        <mesh filename="../meshes/face_shell_3_6_0_mesh.dae" scale="1.0 1.0 1.0"/>
      </geometry>
    </visual>
    <inertial>
      <origin rpy="0 0 0" xyz="0.01418 4e-05 -0.01937"/>
      <mass value="0.14"/>
      <inertia ixx="0.00111143003" ixy="5.69e-09" ixz="5.151886e-05" iyy="0.00055403066" iyz="2.4828e-07" izz="0.0006323271"/>
    </inertial>
  </link>
  <!-- [kg * m^2] -->
  <!-- Fixed joint face face shell -->
  <joint name="base_face_shell_rear" type="fixed">
    <parent link="face_rear"/>
    <child link="face_shell_rear"/>
    <origin rpy="0 0 0" xyz="0 0 0"/>
  </joint>
  <!-- Face shell link -->
  <link name="face_shell_rear">
    <visual>
      <origin rpy="0 0 0" xyz="0 0 0"/>
      <geometry>
        <mesh filename="../meshes/face_shell_3_6_0_mesh.dae" scale="1.0 1.0 1.0"/>
      </geometry>
    </visual>
    <inertial>
      <origin rpy="0 0 0" xyz="0.01418 4e-05 -0.01937"/>
      <mass value="0.14"/>
      <inertia ixx="0.00111143003" ixy="5.69e-09" ixz="5.151886e-05" iyy="0.00055403066" iyz="2.4828e-07" izz="0.0006323271"/>
    </inertial>
  </link>
  <!-- [kg * m^2] -->
  <!-- Fixed joint base battery -->
  <joint name="base_battery" type="fixed">
    <parent link="base"/>
    <child link="battery"/>
    <origin rpy="0 0 0" xyz="0 0 0"/>
  </joint>
  <!-- Shell link -->
  <link name="battery">
    <visual>
      <origin rpy="0 0 0" xyz="0 0 0"/>
      <geometry>
        <mesh filename="../meshes/battery_3_6_0_mesh.dae" scale="1.0 1.0     1.0"/>
      </geometry>
    </visual>
    <inertial>
      <origin rpy="0 0 0" xyz="0.00066 -0.00023 -0.02315"/>
      <mass value="5.65245"/>
      <inertia ixx="0.00779795037" ixy="0.00016392139" ixz="6.976586e-05" iyy="0.07295526813" iyz="1.9919e-06" izz="0.07570041408"/>
    </inertial>
  </link>
  <!-- [kg * m^2] -->
  <!-- Fixed joint to add docking  -->
  <joint name="base_to_docking_socket" type="fixed">
    <parent link="base"/>
    <child link="docking_socket"/>
    <origin rpy="0 0 0" xyz="0.26132 0.0 -0.0617"/>
  </joint>
  <!-- docking socket link -->
  <link name="docking_socket">
    <visual>
      <origin rpy="0 0 0" xyz="0 0 0"/>
      <geometry>
        <mesh filename="../meshes/docking_socket_3_6_0_mesh.dae" scale="1.0 1.0 1.0"/>
      </geometry>
    </visual>
    <inertial>
      <origin rpy="0 0 0" xyz="0.00046 -0.0003 0.0167"/>
      <mass value="0.17724"/>
      <inertia ixx="0.00010383945" ixy="1.06014e-06" ixz="1.17682e-06" iyy="9.58527e-05" iyz="4.5786e-07" izz="0.00017988811"/>
    </inertial>
  </link>
  <link name="imu_link"/>
  <joint name="imu_joint" type="fixed">
    <parent link="base"/>
    <child link="imu_link"/>
    <origin rpy="3.141592653589793 0.0 0.0" xyz="-0.25565 0.00255 0.07672"/>
  </joint>
  <!-- [kg * m^2] -->
  <!-- Camera joint -->
  <joint name="base_to_depth_camera_left_camera" type="fixed">
    <parent link="base"/>
    <child link="depth_camera_left_camera"/>
    <origin rpy="0.0 0.7330382858376184 1.5707963267948966" xyz="-0.025 0.09253 0.01210"/>
  </joint>
  <!-- Camera link -->
  <link name="depth_camera_left_camera">
    <inertial>
      <origin rpy="0 0 0" xyz="-0.01494 0.02558 -0.00194"/>
      <mass value="0.11337"/>
      <inertia ixx="0.00012682371" ixy="1.55568e-06" ixz="2.5635e-07" iyy="2.760233e-05" iyz="1.5728e-07" izz="0.00013532222"/>
    </inertial>
  </link>
  <!-- Camera parent joint -->
  <!-- Frame lies on the left ir camera according to any_realsense2_camera urdf. -->
  <joint name="depth_camera_left_camera_to_camera_parent" type="fixed">
    <parent link="depth_camera_left_camera"/>
    <child link="depth_camera_left_camera_parent"/>
    <origin rpy="0.0 0.0 0.0" xyz="0.0 0.0 0.0"/>
  </joint>
  <!-- Camera parent link -->
  <link name="depth_camera_left_camera_parent"/>
  <!-- simulation or bagfile_is_played -->
  <!-- simulation -->
  <!-- [kg * m^2] -->
  <!-- Camera joint -->
  <joint name="base_to_depth_camera_right_camera" type="fixed">
    <parent link="base"/>
    <child link="depth_camera_right_camera"/>
    <origin rpy="0.0 0.7330382858376184 -1.5707963267948966" xyz="-0.025 -0.09253 0.01210"/>
  </joint>
  <!-- Camera link -->
  <link name="depth_camera_right_camera">
    <inertial>
      <origin rpy="0 0 0" xyz="-0.01494 0.02558 -0.00194"/>
      <mass value="0.11337"/>
      <inertia ixx="0.00012682371" ixy="1.55568e-06" ixz="2.5635e-07" iyy="2.760233e-05" iyz="1.5728e-07" izz="0.00013532222"/>
    </inertial>
  </link>
  <!-- Camera parent joint -->
  <!-- Frame lies on the left ir camera according to any_realsense2_camera urdf. -->
  <joint name="depth_camera_right_camera_to_camera_parent" type="fixed">
    <parent link="depth_camera_right_camera"/>
    <child link="depth_camera_right_camera_parent"/>
    <origin rpy="0.0 0.0 0.0" xyz="0.0 0.0 0.0"/>
  </joint>
  <!-- Camera parent link -->
  <link name="depth_camera_right_camera_parent"/>
  <!-- simulation or bagfile_is_played -->
  <!-- simulation -->
  <!-- [kg * m^2] -->
  <!-- [m] -->
  <!-- Accounts for velodyne cage on top -->
  <!-- parent to sensor joint -->
  <joint name="base_to_lidar" type="fixed">
    <parent link="base"/>
    <child link="lidar"/>
    <origin rpy="0 0 -3.141592653589793" xyz="-0.310 0.0 0.1585"/>
  </joint>
  <!-- Velodyne sensor link -->
  <link name="lidar">
    <visual>
      <origin xyz="0 0 0"/>
      <geometry>
        <mesh filename="../meshes/velodyne_3_6_0_mesh.dae"/>
      </geometry>
    </visual>
    <visual>
      <origin xyz="0 0 0"/>
      <geometry>
        <mesh filename="../meshes/velodyne_guard.dae"/>
      </geometry>
    </visual>
    <inertial>
      <origin rpy="0.0 0.0 0.0" xyz="0.0 -7e-05 0.0021"/>
      <mass value="0.82741"/>
      <inertia ixx="0.00109151797" ixy="6e-11" ixz="6.731e-08" iyy="0.00108715955" iyz="2.04423e-06" izz="0.00116526184"/>
    </inertial>
  </link>
  <!-- simulation -->
  <!-- [m] -->
  <!-- [rad] -->
  <!-- joint base HAA -->
  <joint name="base_LF_HAA_drive" type="fixed">
    <parent link="base"/>
    <child link="LF_HAA_drive"/>
    <origin rpy="0 0 0.0" xyz="0.304 0.109 0.0"/>
  </joint>
  <!-- [kg * m^2] -->
  <!-- [m] -->
  <!-- [A] -->
  <!-- Drive link -->
  <link name="LF_HAA_drive">
    <visual>
      <origin rpy="0 0 0" xyz="0 0 0"/>
      <geometry>
        <mesh filename="../meshes/drive_3_2_0_mesh.dae" scale="1.0 1.0     1.0"/>
      </geometry>
    </visual>
    <inertial>
      <origin rpy="0 0 0" xyz="-0.05783 -0.00014 0.00036"/>
      <mass value="1.9821"/>
      <inertia ixx="0.00231082768" ixy="3.504153e-05" ixz="9.705672e-05" iyy="0.00330180462" iyz="4.358317e-05" izz="0.00321578435"/>
    </inertial>
  </link>
  <!-- Joint Drive output (or parent/output) -->
  <joint name="LF_HAA" type="revolute">
    <parent link="LF_HAA_drive"/>
    <child link="LF_HIP"/>
    <origin rpy="0 0 0" xyz="0 0 0"/>
    <axis xyz="1 0 0"/>
    <limit effort="80.0" velocity="17."/>
    <dynamics damping="0.0" friction="0.0"/>
  </joint>
  <!-- Joint child link (dummy link, dummy inertia required for Gazebo)-->
  <link name="LF_HIP">
    <inertial>
      <origin rpy="0 0 0" xyz="0 0 0"/>
      <mass value="0.001"/>
      <inertia ixx="0.000001" ixy="0.0" ixz="0.0" iyy="0.000001" iyz="0.0" izz="0.000001"/>
    </inertial>
  </link>
  <!-- [kg * m^2] -->
  <!-- [m] -->
  <!-- joint HAA hip -->
  <joint name="LF_HIP_LF_hip_fixed" type="fixed">
    <parent link="LF_HIP"/>
    <child link="LF_hip_fixed"/>
    <origin rpy="0 0 0.0" xyz="0 0 0"/>
  </joint>
  <!-- Hip link -->
  <link name="LF_hip_fixed">
    <visual>
      <origin rpy="0.0 0 0.0" xyz="0 0 0"/>
      <geometry>
        <mesh filename="../meshes/hip_3_6_0_mesh.dae" scale="1.0 1.0     1.0"/>
      </geometry>
    </visual>
    <inertial>
      <origin rpy="0 0 0" xyz="0.03485 -0.00095 0.0"/>
      <mass value="0.32"/>
      <inertia ixx="0.00020753389" ixy="1.68602e-06" ixz="7e-11" iyy="0.00050056267" iyz="9e-11" izz="0.00038587273"/>
    </inertial>
  </link>
  <!-- [rad] -->
  <!-- joint hip to HFE output -->
  <joint name="LF_hip_fixed_LF_HFE_output" type="fixed">
    <parent link="LF_hip_fixed"/>
    <child link="LF_HFE_output"/>
    <origin rpy="0 0 -1.5707963267948966" xyz="0.069 0.006 0.0"/>
  </joint>
  <!-- HFE output (dummy link, dummy inertia required for Gazebo) -->
  <link name="LF_HFE_output">
    <inertial>
      <origin rpy="0 0 0" xyz="0 0 0"/>
      <mass value="0.001"/>
      <inertia ixx="0.000001" ixy="0.0" ixz="0.0" iyy="0.000001" iyz="0.0" izz="0.000001"/>
    </inertial>
  </link>
  <!-- [kg * m^2] -->
  <!-- [m] -->
  <!-- [A] -->
  <!-- Drive link -->
  <link name="LF_HFE_drive">
    <visual>
      <origin rpy="0 0 0" xyz="0 0 0"/>
      <geometry>
        <mesh filename="../meshes/drive_3_2_0_mesh.dae" scale="1.0 1.0     1.0"/>
      </geometry>
    </visual>
    <inertial>
      <origin rpy="0 0 0" xyz="-0.05783 -0.00014 0.00036"/>
      <mass value="1.9821"/>
      <inertia ixx="0.00231082768" ixy="3.504153e-05" ixz="9.705672e-05" iyy="0.00330180462" iyz="4.358317e-05" izz="0.00321578435"/>
    </inertial>
  </link>
  <!-- Joint Drive output (or parent/output) -->
  <joint name="LF_HFE" type="revolute">
    <parent link="LF_HFE_output"/>
    <child link="LF_THIGH"/>
    <origin rpy="0 0 0" xyz="0 0 0"/>
    <axis xyz="-1 0 0"/>
    <limit effort="80.0" velocity="17."/>
    <dynamics damping="0.0" friction="0.0"/>
  </joint>
  <!-- Joint child link (dummy link, dummy inertia required for Gazebo)-->
  <link name="LF_THIGH">
    <inertial>
      <origin rpy="0 0 0" xyz="0 0 0"/>
      <mass value="0.001"/>
      <inertia ixx="0.000001" ixy="0.0" ixz="0.0" iyy="0.000001" iyz="0.0" izz="0.000001"/>
    </inertial>
  </link>
  <joint name="LF_THIGH_to_LF_HFE_drive" type="fixed">
    <parent link="LF_THIGH"/>
    <child link="LF_HFE_drive"/>
    <origin rpy="0 0 0" xyz="0 0 0"/>
  </joint>
  <!-- [kg * m^2] -->
  <!-- [m] -->
  <!-- joint HFE thigh -->
  <joint name="LF_THIGH_LF_thigh_fixed" type="fixed">
    <parent link="LF_HFE_drive"/>
    <child link="LF_thigh_fixed"/>
    <origin rpy="0 0 1.5707963267948966" xyz="0 0 0"/>
  </joint>
  <!-- Thigh link -->
  <link name="LF_thigh_fixed">
    <visual>
      <origin rpy="0 0 0.0" xyz="0 0 0"/>
      <geometry>
        <mesh filename="../meshes/thigh_3_6_0_mesh.dae" scale="1.0 1.0     1.0"/>
      </geometry>
    </visual>
    <inertial>
      <origin rpy="0 0 0" xyz="0.00053 0.0917 -0.13612"/>
      <mass value="1.03672"/>
      <inertia ixx="0.01491122872" ixy="0.00010879729" ixz="0.00015921954" iyy="0.0156542281" iyz="0.0015444376" izz="0.00230981824"/>
    </inertial>
  </link>
  <!-- [rad] -->
  <!-- joint thigh KFE -->
  <joint name="LF_thigh_fixed_LF_KFE_drive" type="fixed">
    <parent link="LF_thigh_fixed"/>
    <child link="LF_KFE_drive"/>
    <origin rpy="0 0 1.5707963267948966" xyz="0.0 0.1805 -0.285"/>
  </joint>
  <!-- [kg * m^2] -->
  <!-- [m] -->
  <!-- [A] -->
  <!-- Drive link -->
  <link name="LF_KFE_drive">
    <visual>
      <origin rpy="0 0 0" xyz="0 0 0"/>
      <geometry>
        <mesh filename="../meshes/drive_3_2_0_mesh.dae" scale="1.0 1.0     1.0"/>
      </geometry>
    </visual>
    <collision>
      <origin rpy="0 1.5707963267948966 0" xyz="-0.0595 0 0"/>
      <geometry>
        <!-- <cylinder length="0.1511" radius="0.07375"/> -->
        <cylinder length="0.01" radius="0.07375"/>
      </geometry>
    </collision>
    <inertial>
      <origin rpy="0 0 0" xyz="-0.05783 -0.00014 0.00036"/>
      <mass value="1.9821"/>
      <inertia ixx="0.00231082768" ixy="3.504153e-05" ixz="9.705672e-05" iyy="0.00330180462" iyz="4.358317e-05" izz="0.00321578435"/>
    </inertial>
  </link>
  <!-- Joint Drive output (or parent/output) -->
  <joint name="LF_KFE" type="revolute">
    <parent link="LF_KFE_drive"/>
    <child link="LF_SHANK"/>
    <origin rpy="0 0 0" xyz="0 0 0"/>
    <axis xyz="1 0 0"/>
    <limit effort="80.0" velocity="17."/>
    <dynamics damping="0.0" friction="0.0"/>
  </joint>
  <!-- Joint child link (dummy link, dummy inertia required for Gazebo)-->
  <link name="LF_SHANK">
    <inertial>
      <origin rpy="0 0 0" xyz="0 0 0"/>
      <mass value="0.001"/>
      <inertia ixx="0.000001" ixy="0.0" ixz="0.0" iyy="0.000001" iyz="0.0" izz="0.000001"/>
    </inertial>
  </link>
  <!-- [m] -->
  <!-- joint KFE shank -->
  <joint name="LF_shank_LF_shank_fixed" type="fixed">
    <parent link="LF_SHANK"/>
    <child link="LF_shank_fixed"/>
    <origin rpy="0 0 -1.5707963267948966" xyz="0 0 0"/>
  </joint>
  <!-- Shank link -->
  <link name="LF_shank_fixed">
    <visual>
      <origin rpy="0 0 0.0" xyz="0 0 0"/>
      <geometry>
        <mesh filename="../meshes/shank_3_6_0_mesh.dae" scale="1.0 1.0     1.0"/>
      </geometry>
    </visual>
    <inertial>
      <origin rpy="0 0 0" xyz="0.02276 0.00909 0.00049"/>
      <mass value="0.48"/>
      <inertia ixx="0.00053103677" ixy="2.43328e-05" ixz="1.696392e-05" iyy="0.00161767282" iyz="1.47873e-06" izz="0.00123097471"/>
    </inertial>
  </link>
  <!-- [kg * m^2] -->
  <!-- Leg configurations: xx (knees bent inwards), xo (knees bent backwards) -->
  <!-- joint shank foot -->
  <joint name="LF_shank_fixed_LF_FOOT" type="fixed" dont_collapse="true">
    <parent link="LF_shank_fixed"/>
    <child link="LF_FOOT"/>
    <origin rpy="0 0 0" xyz="0.1 0.02225 -0.39246"/>
  </joint>
  <!-- Foot link -->
  <link name="LF_FOOT">
    <visual>
      <origin rpy="0 0 0.0" xyz="0 0 0"/>
      <geometry>
        <mesh filename="../meshes/foot_3_6_1_mesh.dae" scale="1.0 1.0     1.0"/>
      </geometry>
    </visual>
    <!-- Foot tube collision -->
    <collision>
      <origin rpy="0 0 0" xyz="0 -0.017210794584401404 0.22582111526138965"/>
      <geometry>
        <cylinder length="0.38849" radius="0.0175"/>
      </geometry>
    </collision>
    <!-- Foot ball collision -->
    <collision>
      <origin xyz="0 -0.008460794584401403 0.03157611526138964"/>
      <geometry>
        <sphere radius="0.03269"/>
      </geometry>
    </collision>
    <inertial>
      <origin rpy="0 0 0" xyz="0.0 -0.01581 0.15902"/>
      <mass value="0.28"/>
      <inertia ixx="0.00479287524" ixy="3.93e-09" ixz="1.01e-09" iyy="0.00478219747" iyz="0.00015345702" izz="0.00010852736"/>
    </inertial>
  </link>
  <!-- [m] -->
  <!-- [rad] -->
  <!-- joint base HAA -->
  <joint name="base_RF_HAA_drive" type="fixed">
    <parent link="base"/>
    <child link="RF_HAA_drive"/>
    <origin rpy="0 0 0.0" xyz="0.304 -0.109 0.0"/>
  </joint>
  <!-- [kg * m^2] -->
  <!-- [m] -->
  <!-- [A] -->
  <!-- Drive link -->
  <link name="RF_HAA_drive">
    <visual>
      <origin rpy="0 0 0" xyz="0 0 0"/>
      <geometry>
        <mesh filename="../meshes/drive_3_2_0_mesh.dae" scale="1.0 1.0     1.0"/>
      </geometry>
    </visual>
    <inertial>
      <origin rpy="0 0 0" xyz="-0.05783 -0.00014 0.00036"/>
      <mass value="1.9821"/>
      <inertia ixx="0.00231082768" ixy="3.504153e-05" ixz="9.705672e-05" iyy="0.00330180462" iyz="4.358317e-05" izz="0.00321578435"/>
    </inertial>
  </link>
  <!-- Joint Drive output (or parent/output) -->
  <joint name="RF_HAA" type="revolute">
    <parent link="RF_HAA_drive"/>
    <child link="RF_HIP"/>
    <origin rpy="0 0 0" xyz="0 0 0"/>
    <axis xyz="1 0 0"/>
    <limit effort="80.0" velocity="17."/>
    <dynamics damping="0.0" friction="0.0"/>
  </joint>
  <!-- Joint child link (dummy link, dummy inertia required for Gazebo)-->
  <link name="RF_HIP">
    <inertial>
      <origin rpy="0 0 0" xyz="0 0 0"/>
      <mass value="0.001"/>
      <inertia ixx="0.000001" ixy="0.0" ixz="0.0" iyy="0.000001" iyz="0.0" izz="0.000001"/>
    </inertial>
  </link>
  <!-- [kg * m^2] -->
  <!-- [m] -->
  <!-- joint HAA hip -->
  <joint name="RF_HIP_RF_hip_fixed" type="fixed">
    <parent link="RF_HIP"/>
    <child link="RF_hip_fixed"/>
    <origin rpy="0 0 0.0" xyz="0 0 0"/>
  </joint>
  <!-- Hip link -->
  <link name="RF_hip_fixed">
    <visual>
      <origin rpy="-3.141592653589793 0 0.0" xyz="0 0 0"/>
      <geometry>
        <mesh filename="../meshes/hip_3_6_0_mesh.dae" scale="1.0 1.0     1.0"/>
      </geometry>
    </visual>
    <inertial>
      <origin rpy="0 0 0" xyz="0.03485 0.00095 0.0"/>
      <mass value="0.32"/>
      <inertia ixx="0.00020753389" ixy="-1.68602e-06" ixz="7e-11" iyy="0.00050056267" iyz="-9e-11" izz="0.00038587273"/>
    </inertial>
  </link>
  <!-- [rad] -->
  <!-- joint hip to HFE output -->
  <joint name="RF_hip_fixed_RF_HFE_output" type="fixed">
    <parent link="RF_hip_fixed"/>
    <child link="RF_HFE_output"/>
    <origin rpy="0 0 1.5707963267948966" xyz="0.069 -0.006 0.0"/>
  </joint>
  <!-- HFE output (dummy link, dummy inertia required for Gazebo) -->
  <link name="RF_HFE_output">
    <inertial>
      <origin rpy="0 0 0" xyz="0 0 0"/>
      <mass value="0.001"/>
      <inertia ixx="0.000001" ixy="0.0" ixz="0.0" iyy="0.000001" iyz="0.0" izz="0.000001"/>
    </inertial>
  </link>
  <!-- [kg * m^2] -->
  <!-- [m] -->
  <!-- [A] -->
  <!-- Drive link -->
  <link name="RF_HFE_drive">
    <visual>
      <origin rpy="0 0 0" xyz="0 0 0"/>
      <geometry>
        <mesh filename="../meshes/drive_3_2_0_mesh.dae" scale="1.0 1.0     1.0"/>
      </geometry>
    </visual>
    <inertial>
      <origin rpy="0 0 0" xyz="-0.05783 -0.00014 0.00036"/>
      <mass value="1.9821"/>
      <inertia ixx="0.00231082768" ixy="3.504153e-05" ixz="9.705672e-05" iyy="0.00330180462" iyz="4.358317e-05" izz="0.00321578435"/>
    </inertial>
  </link>
  <!-- Joint Drive output (or parent/output) -->
  <joint name="RF_HFE" type="revolute">
    <parent link="RF_HFE_output"/>
    <child link="RF_THIGH"/>
    <origin rpy="0 0 0" xyz="0 0 0"/>
    <axis xyz="1 0 0"/>
    <limit effort="80.0" velocity="17."/>
    <dynamics damping="0.0" friction="0.0"/>
  </joint>
  <!-- Joint child link (dummy link, dummy inertia required for Gazebo)-->
  <link name="RF_THIGH">
    <inertial>
      <origin rpy="0 0 0" xyz="0 0 0"/>
      <mass value="0.001"/>
      <inertia ixx="0.000001" ixy="0.0" ixz="0.0" iyy="0.000001" iyz="0.0" izz="0.000001"/>
    </inertial>
  </link>
  <joint name="RF_THIGH_to_RF_HFE_drive" type="fixed">
    <parent link="RF_THIGH"/>
    <child link="RF_HFE_drive"/>
    <origin rpy="0 0 0" xyz="0 0 0"/>
  </joint>
  <!-- [kg * m^2] -->
  <!-- [m] -->
  <!-- joint HFE thigh -->
  <joint name="RF_THIGH_RF_thigh_fixed" type="fixed">
    <parent link="RF_HFE_drive"/>
    <child link="RF_thigh_fixed"/>
    <origin rpy="0 0 -1.5707963267948966" xyz="0 0 0"/>
  </joint>
  <!-- Thigh link -->
  <link name="RF_thigh_fixed">
    <visual>
      <origin rpy="0 0 -3.141592653589793" xyz="0 0 0"/>
      <geometry>
        <mesh filename="../meshes/thigh_3_6_0_mesh.dae" scale="1.0 1.0     1.0"/>
      </geometry>
    </visual>
    <inertial>
      <origin rpy="0 0 0" xyz="0.00053 -0.0917 -0.13612"/>
      <mass value="1.03672"/>
      <inertia ixx="0.01491122872" ixy="-0.00010879729" ixz="0.00015921954" iyy="0.0156542281" iyz="-0.0015444376" izz="0.00230981824"/>
    </inertial>
  </link>
  <!-- [rad] -->
  <!-- joint thigh KFE -->
  <joint name="RF_thigh_fixed_RF_KFE_drive" type="fixed">
    <parent link="RF_thigh_fixed"/>
    <child link="RF_KFE_drive"/>
    <origin rpy="0 0 -1.5707963267948966" xyz="0.0 -0.1805 -0.285"/>
  </joint>
  <!-- [kg * m^2] -->
  <!-- [m] -->
  <!-- [A] -->
  <!-- Drive link -->
  <link name="RF_KFE_drive">
    <visual>
      <origin rpy="0 0 0" xyz="0 0 0"/>
      <geometry>
        <mesh filename="../meshes/drive_3_2_0_mesh.dae" scale="1.0 1.0     1.0"/>
      </geometry>
    </visual>
    <collision>
      <origin rpy="0 1.5707963267948966 0" xyz="-0.0595 0 0"/>
      <geometry>
        <cylinder length="0.01" radius="0.07375"/>
      </geometry>
    </collision>
    <inertial>
      <origin rpy="0 0 0" xyz="-0.05783 -0.00014 0.00036"/>
      <mass value="1.9821"/>
      <inertia ixx="0.00231082768" ixy="3.504153e-05" ixz="9.705672e-05" iyy="0.00330180462" iyz="4.358317e-05" izz="0.00321578435"/>
    </inertial>
  </link>
  <!-- Joint Drive output (or parent/output) -->
  <joint name="RF_KFE" type="revolute">
    <parent link="RF_KFE_drive"/>
    <child link="RF_SHANK"/>
    <origin rpy="0 0 0" xyz="0 0 0"/>
    <axis xyz="-1 0 0"/>
    <limit effort="80.0" velocity="17."/>
    <dynamics damping="0.0" friction="0.0"/>
  </joint>
  <!-- Joint child link (dummy link, dummy inertia required for Gazebo)-->
  <link name="RF_SHANK">
    <inertial>
      <origin rpy="0 0 0" xyz="0 0 0"/>
      <mass value="0.001"/>
      <inertia ixx="0.000001" ixy="0.0" ixz="0.0" iyy="0.000001" iyz="0.0" izz="0.000001"/>
    </inertial>
  </link>
  <!-- [m] -->
  <!-- joint KFE shank -->
  <joint name="RF_shank_RF_shank_fixed" type="fixed">
    <parent link="RF_SHANK"/>
    <child link="RF_shank_fixed"/>
    <origin rpy="0 0 1.5707963267948966" xyz="0 0 0"/>
  </joint>
  <!-- Shank link -->
  <link name="RF_shank_fixed">
    <visual>
      <origin rpy="0 0 0.0" xyz="0 0 0"/>
      <geometry>
        <mesh filename="../meshes/shank_3_6_0_mesh_mirrored.dae" scale="1.0 1.0     1.0"/>
      </geometry>
    </visual>
    <inertial>
      <origin rpy="0 0 0" xyz="0.02276 -0.00909 0.00049"/>
      <mass value="0.48"/>
      <inertia ixx="0.00053103677" ixy="-2.43328e-05" ixz="1.696392e-05" iyy="0.00161767282" iyz="-1.47873e-06" izz="0.00123097471"/>
    </inertial>
  </link>
  <!-- [kg * m^2] -->
  <!-- Leg configurations: xx (knees bent inwards), xo (knees bent backwards) -->
  <!-- joint shank foot -->
  <joint name="RF_shank_fixed_RF_FOOT" type="fixed" dont_collapse="true">
    <parent link="RF_shank_fixed"/>
    <child link="RF_FOOT"/>
    <origin rpy="0 0 0" xyz="0.1 -0.02225 -0.39246"/>
  </joint>
  <!-- Foot link -->
  <link name="RF_FOOT">
    <visual>
      <origin rpy="0 0 -3.141592653589793" xyz="0 0 0"/>
      <geometry>
        <mesh filename="../meshes/foot_3_6_1_mesh.dae" scale="1.0 1.0     1.0"/>
      </geometry>
    </visual>
    <!-- Foot tube collision -->
    <collision>
      <origin rpy="0 0 0" xyz="0 0.017210794584401404 0.22582111526138965"/>
      <geometry>
        <cylinder length="0.38849" radius="0.0175"/>
      </geometry>
    </collision>
    <!-- Foot ball collision -->
    <collision>
      <origin xyz="0 0.008460794584401403 0.03157611526138964"/>
      <geometry>
        <sphere radius="0.03269"/>
      </geometry>
    </collision>
    <inertial>
      <origin rpy="0 0 0" xyz="0.0 0.01581 0.15902"/>
      <mass value="0.28"/>
      <inertia ixx="0.00479287524" ixy="-3.93e-09" ixz="1.01e-09" iyy="0.00478219747" iyz="-0.00015345702" izz="0.00010852736"/>
    </inertial>
  </link>
  <!-- [m] -->
  <!-- [rad] -->
  <!-- joint base HAA -->
  <joint name="base_LH_HAA_drive" type="fixed">
    <parent link="base"/>
    <child link="LH_HAA_drive"/>
    <origin rpy="0 0 -3.141592653589793" xyz="-0.304 0.109 0.0"/>
  </joint>
  <!-- [kg * m^2] -->
  <!-- [m] -->
  <!-- [A] -->
  <!-- Drive link -->
  <link name="LH_HAA_drive">
    <visual>
      <origin rpy="0 0 0" xyz="0 0 0"/>
      <geometry>
        <mesh filename="../meshes/drive_3_2_0_mesh.dae" scale="1.0 1.0     1.0"/>
      </geometry>
    </visual>
    <inertial>
      <origin rpy="0 0 0" xyz="-0.05783 -0.00014 0.00036"/>
      <mass value="1.9821"/>
      <inertia ixx="0.00231082768" ixy="3.504153e-05" ixz="9.705672e-05" iyy="0.00330180462" iyz="4.358317e-05" izz="0.00321578435"/>
    </inertial>
  </link>
  <!-- Joint Drive output (or parent/output) -->
  <joint name="LH_HAA" type="revolute">
    <parent link="LH_HAA_drive"/>
    <child link="LH_HIP"/>
    <origin rpy="0 0 0" xyz="0 0 0"/>
    <axis xyz="-1 0 0"/>
    <limit effort="80.0" velocity="17."/>
    <dynamics damping="0.0" friction="0.0"/>
  </joint>
  <!-- Joint child link (dummy link, dummy inertia required for Gazebo)-->
  <link name="LH_HIP">
    <inertial>
      <origin rpy="0 0 0" xyz="0 0 0"/>
      <mass value="0.001"/>
      <inertia ixx="0.000001" ixy="0.0" ixz="0.0" iyy="0.000001" iyz="0.0" izz="0.000001"/>
    </inertial>
  </link>
  <!-- [kg * m^2] -->
  <!-- [m] -->
  <!-- joint HAA hip -->
  <joint name="LH_HIP_LH_hip_fixed" type="fixed">
    <parent link="LH_HIP"/>
    <child link="LH_hip_fixed"/>
    <origin rpy="0 0 -3.141592653589793" xyz="0 0 0"/>
  </joint>
  <!-- Hip link -->
  <link name="LH_hip_fixed">
    <visual>
      <origin rpy="-3.141592653589793 0 -3.141592653589793" xyz="0 0 0"/>
      <geometry>
        <mesh filename="../meshes/hip_3_6_0_mesh.dae" scale="1.0 1.0     1.0"/>
      </geometry>
    </visual>
    <inertial>
      <origin rpy="0 0 0" xyz="-0.03485 -0.00095 0.0"/>
      <mass value="0.32"/>
      <inertia ixx="0.00020753389" ixy="-1.68602e-06" ixz="-7e-11" iyy="0.00050056267" iyz="9e-11" izz="0.00038587273"/>
    </inertial>
  </link>
  <!-- [rad] -->
  <!-- joint hip to HFE output -->
  <joint name="LH_hip_fixed_LH_HFE_output" type="fixed">
    <parent link="LH_hip_fixed"/>
    <child link="LH_HFE_output"/>
    <origin rpy="0 0 -1.5707963267948966" xyz="-0.069 0.006 0.0"/>
  </joint>
  <!-- HFE output (dummy link, dummy inertia required for Gazebo) -->
  <link name="LH_HFE_output">
    <inertial>
      <origin rpy="0 0 0" xyz="0 0 0"/>
      <mass value="0.001"/>
      <inertia ixx="0.000001" ixy="0.0" ixz="0.0" iyy="0.000001" iyz="0.0" izz="0.000001"/>
    </inertial>
  </link>
  <!-- [kg * m^2] -->
  <!-- [m] -->
  <!-- [A] -->
  <!-- Drive link -->
  <link name="LH_HFE_drive">
    <visual>
      <origin rpy="0 0 0" xyz="0 0 0"/>
      <geometry>
        <mesh filename="../meshes/drive_3_2_0_mesh.dae" scale="1.0 1.0     1.0"/>
      </geometry>
    </visual>
    <inertial>
      <origin rpy="0 0 0" xyz="-0.05783 -0.00014 0.00036"/>
      <mass value="1.9821"/>
      <inertia ixx="0.00231082768" ixy="3.504153e-05" ixz="9.705672e-05" iyy="0.00330180462" iyz="4.358317e-05" izz="0.00321578435"/>
    </inertial>
  </link>
  <!-- Joint Drive output (or parent/output) -->
  <joint name="LH_HFE" type="revolute">
    <parent link="LH_HFE_output"/>
    <child link="LH_THIGH"/>
    <origin rpy="0 0 0" xyz="0 0 0"/>
    <axis xyz="-1 0 0"/>
    <limit effort="80.0" velocity="17."/>
    <dynamics damping="0.0" friction="0.0"/>
  </joint>
  <!-- Joint child link (dummy link, dummy inertia required for Gazebo)-->
  <link name="LH_THIGH">
    <inertial>
      <origin rpy="0 0 0" xyz="0 0 0"/>
      <mass value="0.001"/>
      <inertia ixx="0.000001" ixy="0.0" ixz="0.0" iyy="0.000001" iyz="0.0" izz="0.000001"/>
    </inertial>
  </link>
  <joint name="LH_THIGH_to_LH_HFE_drive" type="fixed">
    <parent link="LH_THIGH"/>
    <child link="LH_HFE_drive"/>
    <origin rpy="0 0 0" xyz="0 0 0"/>
  </joint>
  <!-- [kg * m^2] -->
  <!-- [m] -->
  <!-- joint HFE thigh -->
  <joint name="LH_THIGH_LH_thigh_fixed" type="fixed">
    <parent link="LH_HFE_drive"/>
    <child link="LH_thigh_fixed"/>
    <origin rpy="0 0 1.5707963267948966" xyz="0 0 0"/>
  </joint>
  <!-- Thigh link -->
  <link name="LH_thigh_fixed">
    <visual>
      <origin rpy="0 0 0.0" xyz="0 0 0"/>
      <geometry>
        <mesh filename="../meshes/thigh_3_6_0_mesh.dae" scale="1.0 1.0     1.0"/>
      </geometry>
    </visual>
    <inertial>
      <origin rpy="0 0 0" xyz="-0.00053 0.0917 -0.13612"/>
      <mass value="1.03672"/>
      <inertia ixx="0.01491122872" ixy="-0.00010879729" ixz="-0.00015921954" iyy="0.0156542281" iyz="0.0015444376" izz="0.00230981824"/>
    </inertial>
  </link>
  <!-- [rad] -->
  <!-- joint thigh KFE -->
  <joint name="LH_thigh_fixed_LH_KFE_drive" type="fixed">
    <parent link="LH_thigh_fixed"/>
    <child link="LH_KFE_drive"/>
    <origin rpy="0 0 1.5707963267948966" xyz="-0.0 0.1805 -0.285"/>
  </joint>
  <!-- [kg * m^2] -->
  <!-- [m] -->
  <!-- [A] -->
  <!-- Drive link -->
  <link name="LH_KFE_drive">
    <visual>
      <origin rpy="0 0 0" xyz="0 0 0"/>
      <geometry>
        <mesh filename="../meshes/drive_3_2_0_mesh.dae" scale="1.0 1.0     1.0"/>
      </geometry>
    </visual>
    <collision>
      <origin rpy="0 1.5707963267948966 0" xyz="-0.0595 0 0"/>
      <geometry>
        <cylinder length="0.01" radius="0.07375"/>
      </geometry>
    </collision>
    <inertial>
      <origin rpy="0 0 0" xyz="-0.05783 -0.00014 0.00036"/>
      <mass value="1.9821"/>
      <inertia ixx="0.00231082768" ixy="3.504153e-05" ixz="9.705672e-05" iyy="0.00330180462" iyz="4.358317e-05" izz="0.00321578435"/>
    </inertial>
  </link>
  <!-- Joint Drive output (or parent/output) -->
  <joint name="LH_KFE" type="revolute">
    <parent link="LH_KFE_drive"/>
    <child link="LH_SHANK"/>
    <origin rpy="0 0 0" xyz="0 0 0"/>
    <axis xyz="1 0 0"/>
    <limit effort="80.0" velocity="17."/>
    <dynamics damping="0.0" friction="0.0"/>
  </joint>
  <!-- Joint child link (dummy link, dummy inertia required for Gazebo)-->
  <link name="LH_SHANK">
    <inertial>
      <origin rpy="0 0 0" xyz="0 0 0"/>
      <mass value="0.001"/>
      <inertia ixx="0.000001" ixy="0.0" ixz="0.0" iyy="0.000001" iyz="0.0" izz="0.000001"/>
    </inertial>
  </link>
  <!-- [m] -->
  <!-- joint KFE shank -->
  <joint name="LH_shank_LH_shank_fixed" type="fixed">
    <parent link="LH_SHANK"/>
    <child link="LH_shank_fixed"/>
    <origin rpy="0 0 -1.5707963267948966" xyz="0 0 0"/>
  </joint>
  <!-- Shank link -->
  <link name="LH_shank_fixed">
    <visual>
      <origin rpy="0 0 -3.141592653589793" xyz="0 0 0"/>
      <geometry>
        <mesh filename="../meshes/shank_3_6_0_mesh_mirrored.dae" scale="1.0 1.0     1.0"/>
      </geometry>
    </visual>
    <inertial>
      <origin rpy="0 0 0" xyz="-0.02276 0.00909 0.00049"/>
      <mass value="0.48"/>
      <inertia ixx="0.00053103677" ixy="-2.43328e-05" ixz="-1.696392e-05" iyy="0.00161767282" iyz="1.47873e-06" izz="0.00123097471"/>
    </inertial>
  </link>
  <!-- [kg * m^2] -->
  <!-- Leg configurations: xx (knees bent inwards), xo (knees bent backwards) -->
  <!-- joint shank foot -->
  <joint name="LH_shank_fixed_LH_FOOT" type="fixed" dont_collapse="true">
    <parent link="LH_shank_fixed"/>
    <child link="LH_FOOT"/>
    <origin rpy="0 0 0" xyz="-0.1 0.02225 -0.39246"/>
  </joint>
  <!-- Foot link -->
  <link name="LH_FOOT">
    <visual>
      <origin rpy="0 0 0.0" xyz="0 0 0"/>
      <geometry>
        <mesh filename="../meshes/foot_3_6_1_mesh.dae" scale="1.0 1.0     1.0"/>
      </geometry>
    </visual>
    <!-- Foot tube collision -->
    <collision>
      <origin rpy="0 0 0" xyz="0 -0.017210794584401404 0.22582111526138965"/>
      <geometry>
        <cylinder length="0.38849" radius="0.0175"/>
      </geometry>
    </collision>
    <!-- Foot ball collision -->
    <collision>
      <origin xyz="0 -0.008460794584401403 0.03157611526138964"/>
      <geometry>
        <sphere radius="0.03269"/>
      </geometry>
    </collision>
    <inertial>
      <origin rpy="0 0 0" xyz="-0.0 -0.01581 0.15902"/>
      <mass value="0.28"/>
      <inertia ixx="0.00479287524" ixy="-3.93e-09" ixz="-1.01e-09" iyy="0.00478219747" iyz="0.00015345702" izz="0.00010852736"/>
    </inertial>
  </link>
  <!-- [m] -->
  <!-- [rad] -->
  <!-- joint base HAA -->
  <joint name="base_RH_HAA_drive" type="fixed">
    <parent link="base"/>
    <child link="RH_HAA_drive"/>
    <origin rpy="0 0 -3.141592653589793" xyz="-0.304 -0.109 0.0"/>
  </joint>
  <!-- [kg * m^2] -->
  <!-- [m] -->
  <!-- [A] -->
  <!-- Drive link -->
  <link name="RH_HAA_drive">
    <visual>
      <origin rpy="0 0 0" xyz="0 0 0"/>
      <geometry>
        <mesh filename="../meshes/drive_3_2_0_mesh.dae" scale="1.0 1.0     1.0"/>
      </geometry>
    </visual>
    <inertial>
      <origin rpy="0 0 0" xyz="-0.05783 -0.00014 0.00036"/>
      <mass value="1.9821"/>
      <inertia ixx="0.00231082768" ixy="3.504153e-05" ixz="9.705672e-05" iyy="0.00330180462" iyz="4.358317e-05" izz="0.00321578435"/>
    </inertial>
  </link>
  <!-- Joint Drive output (or parent/output) -->
  <joint name="RH_HAA" type="revolute">
    <parent link="RH_HAA_drive"/>
    <child link="RH_HIP"/>
    <origin rpy="0 0 0" xyz="0 0 0"/>
    <axis xyz="-1 0 0"/>
    <limit effort="80.0" velocity="17."/>
    <dynamics damping="0.0" friction="0.0"/>
  </joint>
  <!-- Joint child link (dummy link, dummy inertia required for Gazebo)-->
  <link name="RH_HIP">
    <inertial>
      <origin rpy="0 0 0" xyz="0 0 0"/>
      <mass value="0.001"/>
      <inertia ixx="0.000001" ixy="0.0" ixz="0.0" iyy="0.000001" iyz="0.0" izz="0.000001"/>
    </inertial>
  </link>
  <!-- [kg * m^2] -->
  <!-- [m] -->
  <!-- joint HAA hip -->
  <joint name="RH_HIP_RH_hip_fixed" type="fixed">
    <parent link="RH_HIP"/>
    <child link="RH_hip_fixed"/>
    <origin rpy="0 0 -3.141592653589793" xyz="0 0 0"/>
  </joint>
  <!-- Hip link -->
  <link name="RH_hip_fixed">
    <visual>
      <origin rpy="0.0 0 -3.141592653589793" xyz="0 0 0"/>
      <geometry>
        <mesh filename="../meshes/hip_3_6_0_mesh.dae" scale="1.0 1.0     1.0"/>
      </geometry>
    </visual>
    <inertial>
      <origin rpy="0 0 0" xyz="-0.03485 0.00095 0.0"/>
      <mass value="0.32"/>
      <inertia ixx="0.00020753389" ixy="1.68602e-06" ixz="-7e-11" iyy="0.00050056267" iyz="-9e-11" izz="0.00038587273"/>
    </inertial>
  </link>
  <!-- [rad] -->
  <!-- joint hip to HFE output -->
  <joint name="RH_hip_fixed_RH_HFE_output" type="fixed">
    <parent link="RH_hip_fixed"/>
    <child link="RH_HFE_output"/>
    <origin rpy="0 0 1.5707963267948966" xyz="-0.069 -0.006 0.0"/>
  </joint>
  <!-- HFE output (dummy link, dummy inertia required for Gazebo) -->
  <link name="RH_HFE_output">
    <inertial>
      <origin rpy="0 0 0" xyz="0 0 0"/>
      <mass value="0.001"/>
      <inertia ixx="0.000001" ixy="0.0" ixz="0.0" iyy="0.000001" iyz="0.0" izz="0.000001"/>
    </inertial>
  </link>
  <!-- [kg * m^2] -->
  <!-- [m] -->
  <!-- [A] -->
  <!-- Drive link -->
  <link name="RH_HFE_drive">
    <visual>
      <origin rpy="0 0 0" xyz="0 0 0"/>
      <geometry>
        <mesh filename="../meshes/drive_3_2_0_mesh.dae" scale="1.0 1.0     1.0"/>
      </geometry>
    </visual>
    <inertial>
      <origin rpy="0 0 0" xyz="-0.05783 -0.00014 0.00036"/>
      <mass value="1.9821"/>
      <inertia ixx="0.00231082768" ixy="3.504153e-05" ixz="9.705672e-05" iyy="0.00330180462" iyz="4.358317e-05" izz="0.00321578435"/>
    </inertial>
  </link>
  <!-- Joint Drive output (or parent/output) -->
  <joint name="RH_HFE" type="revolute">
    <parent link="RH_HFE_output"/>
    <child link="RH_THIGH"/>
    <origin rpy="0 0 0" xyz="0 0 0"/>
    <axis xyz="1 0 0"/>
    <limit effort="80.0" velocity="17."/>
    <dynamics damping="0.0" friction="0.0"/>
  </joint>
  <!-- Joint child link (dummy link, dummy inertia required for Gazebo)-->
  <link name="RH_THIGH">
    <inertial>
      <origin rpy="0 0 0" xyz="0 0 0"/>
      <mass value="0.001"/>
      <inertia ixx="0.000001" ixy="0.0" ixz="0.0" iyy="0.000001" iyz="0.0" izz="0.000001"/>
    </inertial>
  </link>
  <joint name="RH_THIGH_to_RH_HFE_drive" type="fixed">
    <parent link="RH_THIGH"/>
    <child link="RH_HFE_drive"/>
    <origin rpy="0 0 0" xyz="0 0 0"/>
  </joint>
  <!-- [kg * m^2] -->
  <!-- [m] -->
  <!-- joint HFE thigh -->
  <joint name="RH_THIGH_RH_thigh_fixed" type="fixed">
    <parent link="RH_HFE_drive"/>
    <child link="RH_thigh_fixed"/>
    <origin rpy="0 0 -1.5707963267948966" xyz="0 0 0"/>
  </joint>
  <!-- Thigh link -->
  <link name="RH_thigh_fixed">
    <visual>
      <origin rpy="0 0 -3.141592653589793" xyz="0 0 0"/>
      <geometry>
        <mesh filename="../meshes/thigh_3_6_0_mesh.dae" scale="1.0 1.0     1.0"/>
      </geometry>
    </visual>
    <inertial>
      <origin rpy="0 0 0" xyz="-0.00053 -0.0917 -0.13612"/>
      <mass value="1.03672"/>
      <inertia ixx="0.01491122872" ixy="0.00010879729" ixz="-0.00015921954" iyy="0.0156542281" iyz="-0.0015444376" izz="0.00230981824"/>
    </inertial>
  </link>
  <!-- [rad] -->
  <!-- joint thigh KFE -->
  <joint name="RH_thigh_fixed_RH_KFE_drive" type="fixed">
    <parent link="RH_thigh_fixed"/>
    <child link="RH_KFE_drive"/>
    <origin rpy="0 0 -1.5707963267948966" xyz="-0.0 -0.1805 -0.285"/>
  </joint>
  <!-- [kg * m^2] -->
  <!-- [m] -->
  <!-- [A] -->
  <!-- Drive link -->
  <link name="RH_KFE_drive">
    <visual>
      <origin rpy="0 0 0" xyz="0 0 0"/>
      <geometry>
        <mesh filename="../meshes/drive_3_2_0_mesh.dae" scale="1.0 1.0     1.0"/>
      </geometry>
    </visual>
    <collision>
      <origin rpy="0 1.5707963267948966 0" xyz="-0.0595 0 0"/>
      <geometry>
        <cylinder length="0.01" radius="0.07375"/>
      </geometry>
    </collision>
    <inertial>
      <origin rpy="0 0 0" xyz="-0.05783 -0.00014 0.00036"/>
      <mass value="1.9821"/>
      <inertia ixx="0.00231082768" ixy="3.504153e-05" ixz="9.705672e-05" iyy="0.00330180462" iyz="4.358317e-05" izz="0.00321578435"/>
    </inertial>
  </link>
  <!-- Joint Drive output (or parent/output) -->
  <joint name="RH_KFE" type="revolute">
    <parent link="RH_KFE_drive"/>
    <child link="RH_SHANK"/>
    <origin rpy="0 0 0" xyz="0 0 0"/>
    <axis xyz="-1 0 0"/>
    <limit effort="80.0" velocity="17."/>
    <dynamics damping="0.0" friction="0.0"/>
  </joint>
  <!-- Joint child link (dummy link, dummy inertia required for Gazebo)-->
  <link name="RH_SHANK">
    <inertial>
      <origin rpy="0 0 0" xyz="0 0 0"/>
      <mass value="0.001"/>
      <inertia ixx="0.000001" ixy="0.0" ixz="0.0" iyy="0.000001" iyz="0.0" izz="0.000001"/>
    </inertial>
  </link>
  <!-- [m] -->
  <!-- joint KFE shank -->
  <joint name="RH_shank_RH_shank_fixed" type="fixed">
    <parent link="RH_SHANK"/>
    <child link="RH_shank_fixed"/>
    <origin rpy="0 0 1.5707963267948966" xyz="0 0 0"/>
  </joint>
  <!-- Shank link -->
  <link name="RH_shank_fixed">
    <visual>
      <origin rpy="0 0 -3.141592653589793" xyz="0 0 0"/>
      <geometry>
        <mesh filename="../meshes/shank_3_6_0_mesh.dae" scale="1.0 1.0     1.0"/>
      </geometry>
    </visual>
    <inertial>
      <origin rpy="0 0 0" xyz="-0.02276 -0.00909 0.00049"/>
      <mass value="0.48"/>
      <inertia ixx="0.00053103677" ixy="2.43328e-05" ixz="-1.696392e-05" iyy="0.00161767282" iyz="-1.47873e-06" izz="0.00123097471"/>
    </inertial>
  </link>
  <!-- [kg * m^2] -->
  <!-- Leg configurations: xx (knees bent inwards), xo (knees bent backwards) -->
  <!-- joint shank foot -->
  <joint name="RH_shank_fixed_RH_FOOT" type="fixed" dont_collapse="true">
    <parent link="RH_shank_fixed"/>
    <child link="RH_FOOT"/>
    <origin rpy="0 0 0" xyz="-0.1 -0.02225 -0.39246"/>
  </joint>
  <!-- Foot link -->
  <link name="RH_FOOT">
    <visual>
      <origin rpy="0 0 -3.141592653589793" xyz="0 0 0"/>
      <geometry>
        <mesh filename="../meshes/foot_3_6_1_mesh.dae" scale="1.0 1.0     1.0"/>
      </geometry>
    </visual>
    <!-- Foot tube collision -->
    <collision>
      <origin rpy="0 0 0" xyz="0 0.017210794584401404 0.22582111526138965"/>
      <geometry>
        <cylinder length="0.38849" radius="0.0175"/>
      </geometry>
    </collision>
    <!-- Foot ball collision -->
    <collision>
      <origin xyz="0 0.008460794584401403 0.03157611526138964"/>
      <geometry>
        <sphere radius="0.03269"/>
      </geometry>
    </collision>
    <inertial>
      <origin rpy="0 0 0" xyz="-0.0 0.01581 0.15902"/>
      <mass value="0.28"/>
      <inertia ixx="0.00479287524" ixy="3.93e-09" ixz="-1.01e-09" iyy="0.00478219747" iyz="-0.00015345702" izz="0.00010852736"/>
    </inertial>
  </link>
  <joint name="base_to_inspection_payload_mount" type="fixed">
    <parent link="base"/>
    <child link="inspection_payload_mount"/>
    <origin rpy="0 0 0" xyz="0.14253 0.0 0.092"/>
  </joint>
  <link name="inspection_payload_mount">
    <visual>
      <origin rpy="0 0 0" xyz="0 0 0.0"/>
      <geometry>
        <mesh filename="../meshes/mount_3_6_0.dae" scale="1 1 1"/>
      </geometry>
    </visual>
    <inertial>
      <!-- These inertial parameters are adapted and based on the estimate that the bigger portion of the weight
         is in the pan link (1/2), the intertial matrix is derived from a cube with 0.4 m length on each dimension
         (diagonal elements) and the others are not meaningful. -->
      <origin rpy="0 0 0" xyz="0.00290 0.00 0.01050"/>
      <mass value="0.21580"/>
      <inertia ixx="0.00023461260" ixy="0.00000000486" ixz="0.00000355757" iyy="0.00020272719" iyz="0.00000000936" izz="0.00040505639"/>
      <!-- These inertial parameters consider the whole pantilt head unit as a single rigid body.
        <origin xyz="-0.0046 0.0046 0.0686" rpy="0 0 0"/>
        <mass value="2.26"/>
        <inertia ixx="0.01246" ixy= "-0.000227" ixz="0.00053"
                 iyy="0.007706" iyz="-0.000527" izz="0.008967"/>
         -->
    </inertial>
  </link>
</robot>
